Workbook

Sheet Disponibilidad
T1: % Disponibilidad
G2: Últimos 12 Meses | T2: =((COUNTIF(TblDisponibilidad[Estado],"NORMO STOCK"))+(COUNTIF(TblDisponibilidad[Estado],"SOBRE STOCK")))/(((COUNTIF(TblDisponibilidad[Estado],"<>solid"))-(COUNTIF(TblDisponibilidad[Estado],"=No Rota"))-(COUNTBLANK(TblDisponibilidad[Estado])))) -> #DIV/0!
A3: Código | B3: Descripción | C3: Concentración | D3: Presentación | E3: Forma Farmacéutica | F3: Tipo | G3: ago-21 | H3: sep-21 | I3: oct-21 | J3: nov-21 | K3: dic-21 | L3: ene-22 | M3: feb-22 | N3: mar-22 | O3: abr-22 | P3: may-22 | Q3: jun-22 | R3: jul-22 | S3: CPMA | T3: Stock | U3: Meses rotación | V3: Meses abastecidos | W3: Estado | X3: PNUMEN MEDICAMENTOS | Y3: PNUMEN MATERIAL MEDICO | Z3: ESTRATEGIA MEDICAMENTOS | AA3: ESTRATEGIA MATERIAL MEDICO

Sheet Disp SIS
R1: % para SIS | S1: =(COUNTIF(Tabla1[Estado],"no rota")+COUNTIF(Tabla1[Estado],"NORMO STOCK")+COUNTIF(Tabla1[Estado],"SOBRE STOCK"))/(COUNTIF(Tabla1[Estado],"<>solid")-COUNTBLANK(Tabla1[Estado])-COUNTIF(Tabla1[Estado],"no incluido")) -> 0
A2: SISMED | B2: PRODUCTO | C2: ago-21 | D2: sep-21 | E2: oct-21 | F2: nov-21 | G2: dic-21 | H2: ene-22 | I2: feb-22 | J2: mar-22 | K2: abr-22 | L2: may-22 | M2: jun-22 | N2: jul-22 | O2: CPMA SIS | P2: Meses Rotacion | Q2: Stock | R2: Meses Abastecidos | S2: Estado
A3: 00091 | B3: =IFERROR(VLOOKUP(Tabla1[[#This Row],[SISMED]],TblDisponibilidad[],2,FALSE), "") | C3: =IFERROR(VLOOKUP(Tabla1[[#This Row],[SISMED]],TblDisponibilidad[],7,FALSE), 0) -> 0 | D3: =IFERROR(VLOOKUP(Tabla1[[#This Row],[SISMED]],TblDisponibilidad[],8,FALSE), 0) -> 0 | E3: =IFERROR(VLOOKUP(Tabla1[[#This Row],[SISMED]],TblDisponibilidad[],9,FALSE), 0) -> 0 | F3: =IFERROR(VLOOKUP(Tabla1[[#This Row],[SISMED]],TblDisponibilidad[],10,FALSE), 0) -> 0 | G3: =IFERROR(VLOOKUP(Tabla1[[#This Row],[SISMED]],TblDisponibilidad[],11,FALSE), 0) -> 0 | H3: =IFERROR(VLOOKUP(Tabla1[[#This Row],[SISMED]],TblDisponibilidad[],12,FALSE), 0) -> 0 | I3: =IFERROR(VLOOKUP(Tabla1[[#This Row],[SISMED]],TblDisponibilidad[],13,FALSE), 0) -> 0 | J3: =IFERROR(VLOOKUP(Tabla1[[#This Row],[SISMED]],TblDisponibilidad[],14,FALSE), 0) -> 0 | K3: =IFERROR(VLOOKUP(Tabla1[[#This Row],[SISMED]],TblDisponibilidad[],15,FALSE), 0) -> 0 | L3: =IFERROR(VLOOKUP(Tabla1[[#This Row],[SISMED]],TblDisponibilidad[],16,FALSE), 0) -> 0 | M3: =IFERROR(VLOOKUP(Tabla1[[#This Row],[SISMED]],TblDisponibilidad[],17,FALSE), 0) -> 0 | N3: =IFERROR(VLOOKUP(Tabla1[[#This Row],[SISMED]],TblDisponibilidad[],18,FALSE), 0) -> 0 | O3: =IFERROR(VLOOKUP(Tabla1[[#This Row],[SISMED]],TblDisponibilidad[],19,FALSE), 0) -> 0 | P3: =IFERROR(VLOOKUP(Tabla1[[#This Row],[SISMED]],TblDisponibilidad[],20,FALSE), 0) -> 0 | Q3: =IFERROR(VLOOKUP(Tabla1[[#This Row],[SISMED]],TblDisponibilidad[],21,FALSE), 0) -> 0 | R3: =IFERROR(VLOOKUP(Tabla1[[#This Row],[SISMED]],TblDisponibilidad[],22,FALSE), 0) -> 0 | S3: =IFERROR(VLOOKUP(Tabla1[[#This Row],[SISMED]],TblDisponibilidad[],23,FALSE), 0) -> 0
A4: 00095 | B4: =IFERROR(VLOOKUP(Tabla1[[#This Row],[SISMED]],TblDisponibilidad[],2,FALSE), "") | C4: =IFERROR(VLOOKUP(Tabla1[[#This Row],[SISMED]],TblDisponibilidad[],7,FALSE), 0) -> 0 | D4: =IFERROR(VLOOKUP(Tabla1[[#This Row],[SISMED]],TblDisponibilidad[],8,FALSE), 0) -> 0 | E4: =IFERROR(VLOOKUP(Tabla1[[#This Row],[SISMED]],TblDisponibilidad[],9,FALSE), 0) -> 0 | F4: =IFERROR(VLOOKUP(Tabla1[[#This Row],[SISMED]],TblDisponibilidad[],10,FALSE), 0) -> 0 | G4: =IFERROR(VLOOKUP(Tabla1[[#This Row],[SISMED]],TblDisponibilidad[],11,FALSE), 0) -> 0 | H4: =IFERROR(VLOOKUP(Tabla1[[#This Row],[SISMED]],TblDisponibilidad[],12,FALSE), 0) -> 0 | I4: =IFERROR(VLOOKUP(Tabla1[[#This Row],[SISMED]],TblDisponibilidad[],13,FALSE), 0) -> 0 | J4: =IFERROR(VLOOKUP(Tabla1[[#This Row],[SISMED]],TblDisponibilidad[],14,FALSE), 0) -> 0 | K4: =IFERROR(VLOOKUP(Tabla1[[#This Row],[SISMED]],TblDisponibilidad[],15,FALSE), 0) -> 0 | L4: =IFERROR(VLOOKUP(Tabla1[[#This Row],[SISMED]],TblDisponibilidad[],16,FALSE), 0) -> 0 | M4: =IFERROR(VLOOKUP(Tabla1[[#This Row],[SISMED]],TblDisponibilidad[],17,FALSE), 0) -> 0 | N4: =IFERROR(VLOOKUP(Tabla1[[#This Row],[SISMED]],TblDisponibilidad[],18,FALSE), 0) -> 0 | O4: =IFERROR(VLOOKUP(Tabla1[[#This Row],[SISMED]],TblDisponibilidad[],19,FALSE), 0) -> 0 | P4: =IFERROR(VLOOKUP(Tabla1[[#This Row],[SISMED]],TblDisponibilidad[],20,FALSE), 0) -> 0 | Q4: =IFERROR(VLOOKUP(Tabla1[[#This Row],[SISMED]],TblDisponibilidad[],21,FALSE), 0) -> 0 | R4: =IFERROR(VLOOKUP(Tabla1[[#This Row],[SISMED]],TblDisponibilidad[],22,FALSE), 0) -> 0 | S4: =IFERROR(VLOOKUP(Tabla1[[#This Row],[SISMED]],TblDisponibilidad[],23,FALSE), 0) -> 0
A5: 00111 | B5: =IFERROR(VLOOKUP(Tabla1[[#This Row],[SISMED]],TblDisponibilidad[],2,FALSE), "") | C5: =IFERROR(VLOOKUP(Tabla1[[#This Row],[SISMED]],TblDisponibilidad[],7,FALSE), 0) -> 0 | D5: =IFERROR(VLOOKUP(Tabla1[[#This Row],[SISMED]],TblDisponibilidad[],8,FALSE), 0) -> 0 | E5: =IFERROR(VLOOKUP(Tabla1[[#This Row],[SISMED]],TblDisponibilidad[],9,FALSE), 0) -> 0 | F5: =IFERROR(VLOOKUP(Tabla1[[#This Row],[SISMED]],TblDisponibilidad[],10,FALSE), 0) -> 0 | G5: =IFERROR(VLOOKUP(Tabla1[[#This Row],[SISMED]],TblDisponibilidad[],11,FALSE), 0) -> 0 | H5: =IFERROR(VLOOKUP(Tabla1[[#This Row],[SISMED]],TblDisponibilidad[],12,FALSE), 0) -> 0 | I5: =IFERROR(VLOOKUP(Tabla1[[#This Row],[SISMED]],TblDisponibilidad[],13,FALSE), 0) -> 0 | J5: =IFERROR(VLOOKUP(Tabla1[[#This Row],[SISMED]],TblDisponibilidad[],14,FALSE), 0) -> 0 | K5: =IFERROR(VLOOKUP(Tabla1[[#This Row],[SISMED]],TblDisponibilidad[],15,FALSE), 0) -> 0 | L5: =IFERROR(VLOOKUP(Tabla1[[#This Row],[SISMED]],TblDisponibilidad[],16,FALSE), 0) -> 0 | M5: =IFERROR(VLOOKUP(Tabla1[[#This Row],[SISMED]],TblDisponibilidad[],17,FALSE), 0) -> 0 | N5: =IFERROR(VLOOKUP(Tabla1[[#This Row],[SISMED]],TblDisponibilidad[],18,FALSE), 0) -> 0 | O5: =IFERROR(VLOOKUP(Tabla1[[#This Row],[SISMED]],TblDisponibilidad[],19,FALSE), 0) -> 0 | P5: =IFERROR(VLOOKUP(Tabla1[[#This Row],[SISMED]],TblDisponibilidad[],20,FALSE), 0) -> 0 | Q5: =IFERROR(VLOOKUP(Tabla1[[#This Row],[SISMED]],TblDisponibilidad[],21,FALSE), 0) -> 0 | R5: =IFERROR(VLOOKUP(Tabla1[[#This Row],[SISMED]],TblDisponibilidad[],22,FALSE), 0) -> 0 | S5: =IFERROR(VLOOKUP(Tabla1[[#This Row],[SISMED]],TblDisponibilidad[],23,FALSE), 0) -> 0
A6: 00132 | B6: =IFERROR(VLOOKUP(Tabla1[[#This Row],[SISMED]],TblDisponibilidad[],2,FALSE), "") | C6: =IFERROR(VLOOKUP(Tabla1[[#This Row],[SISMED]],TblDisponibilidad[],7,FALSE), 0) -> 0 | D6: =IFERROR(VLOOKUP(Tabla1[[#This Row],[SISMED]],TblDisponibilidad[],8,FALSE), 0) -> 0 | E6: =IFERROR(VLOOKUP(Tabla1[[#This Row],[SISMED]],TblDisponibilidad[],9,FALSE), 0) -> 0 | F6: =IFERROR(VLOOKUP(Tabla1[[#This Row],[SISMED]],TblDisponibilidad[],10,FALSE), 0) -> 0 | G6: =IFERROR(VLOOKUP(Tabla1[[#This Row],[SISMED]],TblDisponibilidad[],11,FALSE), 0) -> 0 | H6: =IFERROR(VLOOKUP(Tabla1[[#This Row],[SISMED]],TblDisponibilidad[],12,FALSE), 0) -> 0 | I6: =IFERROR(VLOOKUP(Tabla1[[#This Row],[SISMED]],TblDisponibilidad[],13,FALSE), 0) -> 0 | J6: =IFERROR(VLOOKUP(Tabla1[[#This Row],[SISMED]],TblDisponibilidad[],14,FALSE), 0) -> 0 | K6: =IFERROR(VLOOKUP(Tabla1[[#This Row],[SISMED]],TblDisponibilidad[],15,FALSE), 0) -> 0 | L6: =IFERROR(VLOOKUP(Tabla1[[#This Row],[SISMED]],TblDisponibilidad[],16,FALSE), 0) -> 0 | M6: =IFERROR(VLOOKUP(Tabla1[[#This Row],[SISMED]],TblDisponibilidad[],17,FALSE), 0) -> 0 | N6: =IFERROR(VLOOKUP(Tabla1[[#This Row],[SISMED]],TblDisponibilidad[],18,FALSE), 0) -> 0 | O6: =IFERROR(VLOOKUP(Tabla1[[#This Row],[SISMED]],TblDisponibilidad[],19,FALSE), 0) -> 0 | P6: =IFERROR(VLOOKUP(Tabla1[[#This Row],[SISMED]],TblDisponibilidad[],20,FALSE), 0) -> 0 | Q6: =IFERROR(VLOOKUP(Tabla1[[#This Row],[SISMED]],TblDisponibilidad[],21,FALSE), 0) -> 0 | R6: =IFERROR(VLOOKUP(Tabla1[[#This Row],[SISMED]],TblDisponibilidad[],22,FALSE), 0) -> 0 | S6: =IFERROR(VLOOKUP(Tabla1[[#This Row],[SISMED]],TblDisponibilidad[],23,FALSE), 0) -> 0
A7: 00143 | B7: =IFERROR(VLOOKUP(Tabla1[[#This Row],[SISMED]],TblDisponibilidad[],2,FALSE), "") | C7: =IFERROR(VLOOKUP(Tabla1[[#This Row],[SISMED]],TblDisponibilidad[],7,FALSE), 0) -> 0 | D7: =IFERROR(VLOOKUP(Tabla1[[#This Row],[SISMED]],TblDisponibilidad[],8,FALSE), 0) -> 0 | E7: =IFERROR(VLOOKUP(Tabla1[[#This Row],[SISMED]],TblDisponibilidad[],9,FALSE), 0) -> 0 | F7: =IFERROR(VLOOKUP(Tabla1[[#This Row],[SISMED]],TblDisponibilidad[],10,FALSE), 0) -> 0 | G7: =IFERROR(VLOOKUP(Tabla1[[#This Row],[SISMED]],TblDisponibilidad[],11,FALSE), 0) -> 0 | H7: =IFERROR(VLOOKUP(Tabla1[[#This Row],[SISMED]],TblDisponibilidad[],12,FALSE), 0) -> 0 | I7: =IFERROR(VLOOKUP(Tabla1[[#This Row],[SISMED]],TblDisponibilidad[],13,FALSE), 0) -> 0 | J7: =IFERROR(VLOOKUP(Tabla1[[#This Row],[SISMED]],TblDisponibilidad[],14,FALSE), 0) -> 0 | K7: =IFERROR(VLOOKUP(Tabla1[[#This Row],[SISMED]],TblDisponibilidad[],15,FALSE), 0) -> 0 | L7: =IFERROR(VLOOKUP(Tabla1[[#This Row],[SISMED]],TblDisponibilidad[],16,FALSE), 0) -> 0 | M7: =IFERROR(VLOOKUP(Tabla1[[#This Row],[SISMED]],TblDisponibilidad[],17,FALSE), 0) -> 0 | N7: =IFERROR(VLOOKUP(Tabla1[[#This Row],[SISMED]],TblDisponibilidad[],18,FALSE), 0) -> 0 | O7: =IFERROR(VLOOKUP(Tabla1[[#This Row],[SISMED]],TblDisponibilidad[],19,FALSE), 0) -> 0 | P7: =IFERROR(VLOOKUP(Tabla1[[#This Row],[SISMED]],TblDisponibilidad[],20,FALSE), 0) -> 0 | Q7: =IFERROR(VLOOKUP(Tabla1[[#This Row],[SISMED]],TblDisponibilidad[],21,FALSE), 0) -> 0 | R7: =IFERROR(VLOOKUP(Tabla1[[#This Row],[SISMED]],TblDisponibilidad[],22,FALSE), 0) -> 0 | S7: =IFERROR(VLOOKUP(Tabla1[[#This Row],[SISMED]],TblDisponibilidad[],23,FALSE), 0) -> 0
A8: 00200 | B8: =IFERROR(VLOOKUP(Tabla1[[#This Row],[SISMED]],TblDisponibilidad[],2,FALSE), "") | C8: =IFERROR(VLOOKUP(Tabla1[[#This Row],[SISMED]],TblDisponibilidad[],7,FALSE), 0) -> 0 | D8: =IFERROR(VLOOKUP(Tabla1[[#This Row],[SISMED]],TblDisponibilidad[],8,FALSE), 0) -> 0 | E8: =IFERROR(VLOOKUP(Tabla1[[#This Row],[SISMED]],TblDisponibilidad[],9,FALSE), 0) -> 0 | F8: =IFERROR(VLOOKUP(Tabla1[[#This Row],[SISMED]],TblDisponibilidad[],10,FALSE), 0) -> 0 | G8: =IFERROR(VLOOKUP(Tabla1[[#This Row],[SISMED]],TblDisponibilidad[],11,FALSE), 0) -> 0 | H8: =IFERROR(VLOOKUP(Tabla1[[#This Row],[SISMED]],TblDisponibilidad[],12,FALSE), 0) -> 0 | I8: =IFERROR(VLOOKUP(Tabla1[[#This Row],[SISMED]],TblDisponibilidad[],13,FALSE), 0) -> 0 | J8: =IFERROR(VLOOKUP(Tabla1[[#This Row],[SISMED]],TblDisponibilidad[],14,FALSE), 0) -> 0 | K8: =IFERROR(VLOOKUP(Tabla1[[#This Row],[SISMED]],TblDisponibilidad[],15,FALSE), 0) -> 0 | L8: =IFERROR(VLOOKUP(Tabla1[[#This Row],[SISMED]],TblDisponibilidad[],16,FALSE), 0) -> 0 | M8: =IFERROR(VLOOKUP(Tabla1[[#This Row],[SISMED]],TblDisponibilidad[],17,FALSE), 0) -> 0 | N8: =IFERROR(VLOOKUP(Tabla1[[#This Row],[SISMED]],TblDisponibilidad[],18,FALSE), 0) -> 0 | O8: =IFERROR(VLOOKUP(Tabla1[[#This Row],[SISMED]],TblDisponibilidad[],19,FALSE), 0) -> 0 | P8: =IFERROR(VLOOKUP(Tabla1[[#This Row],[SISMED]],TblDisponibilidad[],20,FALSE), 0) -> 0 | Q8: =IFERROR(VLOOKUP(Tabla1[[#This Row],[SISMED]],TblDisponibilidad[],21,FALSE), 0) -> 0 | R8: =IFERROR(VLOOKUP(Tabla1[[#This Row],[SISMED]],TblDisponibilidad[],22,FALSE), 0) -> 0 | S8: =IFERROR(VLOOKUP(Tabla1[[#This Row],[SISMED]],TblDisponibilidad[],23,FALSE), 0) -> 0
A9: 00223 | B9: =IFERROR(VLOOKUP(Tabla1[[#This Row],[SISMED]],TblDisponibilidad[],2,FALSE), "") | C9: =IFERROR(VLOOKUP(Tabla1[[#This Row],[SISMED]],TblDisponibilidad[],7,FALSE), 0) -> 0 | D9: =IFERROR(VLOOKUP(Tabla1[[#This Row],[SISMED]],TblDisponibilidad[],8,FALSE), 0) -> 0 | E9: =IFERROR(VLOOKUP(Tabla1[[#This Row],[SISMED]],TblDisponibilidad[],9,FALSE), 0) -> 0 | F9: =IFERROR(VLOOKUP(Tabla1[[#This Row],[SISMED]],TblDisponibilidad[],10,FALSE), 0) -> 0 | G9: =IFERROR(VLOOKUP(Tabla1[[#This Row],[SISMED]],TblDisponibilidad[],11,FALSE), 0) -> 0 | H9: =IFERROR(VLOOKUP(Tabla1[[#This Row],[SISMED]],TblDisponibilidad[],12,FALSE), 0) -> 0 | I9: =IFERROR(VLOOKUP(Tabla1[[#This Row],[SISMED]],TblDisponibilidad[],13,FALSE), 0) -> 0 | J9: =IFERROR(VLOOKUP(Tabla1[[#This Row],[SISMED]],TblDisponibilidad[],14,FALSE), 0) -> 0 | K9: =IFERROR(VLOOKUP(Tabla1[[#This Row],[SISMED]],TblDisponibilidad[],15,FALSE), 0) -> 0 | L9: =IFERROR(VLOOKUP(Tabla1[[#This Row],[SISMED]],TblDisponibilidad[],16,FALSE), 0) -> 0 | M9: =IFERROR(VLOOKUP(Tabla1[[#This Row],[SISMED]],TblDisponibilidad[],17,FALSE), 0) -> 0 | N9: =IFERROR(VLOOKUP(Tabla1[[#This Row],[SISMED]],TblDisponibilidad[],18,FALSE), 0) -> 0 | O9: =IFERROR(VLOOKUP(Tabla1[[#This Row],[SISMED]],TblDisponibilidad[],19,FALSE), 0) -> 0 | P9: =IFERROR(VLOOKUP(Tabla1[[#This Row],[SISMED]],TblDisponibilidad[],20,FALSE), 0) -> 0 | Q9: =IFERROR(VLOOKUP(Tabla1[[#This Row],[SISMED]],TblDisponibilidad[],21,FALSE), 0) -> 0 | R9: =IFERROR(VLOOKUP(Tabla1[[#This Row],[SISMED]],TblDisponibilidad[],22,FALSE), 0) -> 0 | S9: =IFERROR(VLOOKUP(Tabla1[[#This Row],[SISMED]],TblDisponibilidad[],23,FALSE), 0) -> 0
A10: 00225 | B10: =IFERROR(VLOOKUP(Tabla1[[#This Row],[SISMED]],TblDisponibilidad[],2,FALSE), "") | C10: =IFERROR(VLOOKUP(Tabla1[[#This Row],[SISMED]],TblDisponibilidad[],7,FALSE), 0) -> 0 | D10: =IFERROR(VLOOKUP(Tabla1[[#This Row],[SISMED]],TblDisponibilidad[],8,FALSE), 0) -> 0 | E10: =IFERROR(VLOOKUP(Tabla1[[#This Row],[SISMED]],TblDisponibilidad[],9,FALSE), 0) -> 0 | F10: =IFERROR(VLOOKUP(Tabla1[[#This Row],[SISMED]],TblDisponibilidad[],10,FALSE), 0) -> 0 | G10: =IFERROR(VLOOKUP(Tabla1[[#This Row],[SISMED]],TblDisponibilidad[],11,FALSE), 0) -> 0 | H10: =IFERROR(VLOOKUP(Tabla1[[#This Row],[SISMED]],TblDisponibilidad[],12,FALSE), 0) -> 0 | I10: =IFERROR(VLOOKUP(Tabla1[[#This Row],[SISMED]],TblDisponibilidad[],13,FALSE), 0) -> 0 | J10: =IFERROR(VLOOKUP(Tabla1[[#This Row],[SISMED]],TblDisponibilidad[],14,FALSE), 0) -> 0 | K10: =IFERROR(VLOOKUP(Tabla1[[#This Row],[SISMED]],TblDisponibilidad[],15,FALSE), 0) -> 0 | L10: =IFERROR(VLOOKUP(Tabla1[[#This Row],[SISMED]],TblDisponibilidad[],16,FALSE), 0) -> 0 | M10: =IFERROR(VLOOKUP(Tabla1[[#This Row],[SISMED]],TblDisponibilidad[],17,FALSE), 0) -> 0 | N10: =IFERROR(VLOOKUP(Tabla1[[#This Row],[SISMED]],TblDisponibilidad[],18,FALSE), 0) -> 0 | O10: =IFERROR(VLOOKUP(Tabla1[[#This Row],[SISMED]],TblDisponibilidad[],19,FALSE), 0) -> 0 | P10: =IFERROR(VLOOKUP(Tabla1[[#This Row],[SISMED]],TblDisponibilidad[],20,FALSE), 0) -> 0 | Q10: =IFERROR(VLOOKUP(Tabla1[[#This Row],[SISMED]],TblDisponibilidad[],21,FALSE), 0) -> 0 | R10: =IFERROR(VLOOKUP(Tabla1[[#This Row],[SISMED]],TblDisponibilidad[],22,FALSE), 0) -> 0 | S10: =IFERROR(VLOOKUP(Tabla1[[#This Row],[SISMED]],TblDisponibilidad[],23,FALSE), 0) -> 0
A11: 00234 | B11: =IFERROR(VLOOKUP(Tabla1[[#This Row],[SISMED]],TblDisponibilidad[],2,FALSE), "") | C11: =IFERROR(VLOOKUP(Tabla1[[#This Row],[SISMED]],TblDisponibilidad[],7,FALSE), 0) -> 0 | D11: =IFERROR(VLOOKUP(Tabla1[[#This Row],[SISMED]],TblDisponibilidad[],8,FALSE), 0) -> 0 | E11: =IFERROR(VLOOKUP(Tabla1[[#This Row],[SISMED]],TblDisponibilidad[],9,FALSE), 0) -> 0 | F11: =IFERROR(VLOOKUP(Tabla1[[#This Row],[SISMED]],TblDisponibilidad[],10,FALSE), 0) -> 0 | G11: =IFERROR(VLOOKUP(Tabla1[[#This Row],[SISMED]],TblDisponibilidad[],11,FALSE), 0) -> 0 | H11: =IFERROR(VLOOKUP(Tabla1[[#This Row],[SISMED]],TblDisponibilidad[],12,FALSE), 0) -> 0 | I11: =IFERROR(VLOOKUP(Tabla1[[#This Row],[SISMED]],TblDisponibilidad[],13,FALSE), 0) -> 0 | J11: =IFERROR(VLOOKUP(Tabla1[[#This Row],[SISMED]],TblDisponibilidad[],14,FALSE), 0) -> 0 | K11: =IFERROR(VLOOKUP(Tabla1[[#This Row],[SISMED]],TblDisponibilidad[],15,FALSE), 0) -> 0 | L11: =IFERROR(VLOOKUP(Tabla1[[#This Row],[SISMED]],TblDisponibilidad[],16,FALSE), 0) -> 0 | M11: =IFERROR(VLOOKUP(Tabla1[[#This Row],[SISMED]],TblDisponibilidad[],17,FALSE), 0) -> 0 | N11: =IFERROR(VLOOKUP(Tabla1[[#This Row],[SISMED]],TblDisponibilidad[],18,FALSE), 0) -> 0 | O11: =IFERROR(VLOOKUP(Tabla1[[#This Row],[SISMED]],TblDisponibilidad[],19,FALSE), 0) -> 0 | P11: =IFERROR(VLOOKUP(Tabla1[[#This Row],[SISMED]],TblDisponibilidad[],20,FALSE), 0) -> 0 | Q11: =IFERROR(VLOOKUP(Tabla1[[#This Row],[SISMED]],TblDisponibilidad[],21,FALSE), 0) -> 0 | R11: =IFERROR(VLOOKUP(Tabla1[[#This Row],[SISMED]],TblDisponibilidad[],22,FALSE), 0) -> 0 | S11: =IFERROR(VLOOKUP(Tabla1[[#This Row],[SISMED]],TblDisponibilidad[],23,FALSE), 0) -> 0
A12: 00259 | B12: =IFERROR(VLOOKUP(Tabla1[[#This Row],[SISMED]],TblDisponibilidad[],2,FALSE), "") | C12: =IFERROR(VLOOKUP(Tabla1[[#This Row],[SISMED]],TblDisponibilidad[],7,FALSE), 0) -> 0 | D12: =IFERROR(VLOOKUP(Tabla1[[#This Row],[SISMED]],TblDisponibilidad[],8,FALSE), 0) -> 0 | E12: =IFERROR(VLOOKUP(Tabla1[[#This Row],[SISMED]],TblDisponibilidad[],9,FALSE), 0) -> 0 | F12: =IFERROR(VLOOKUP(Tabla1[[#This Row],[SISMED]],TblDisponibilidad[],10,FALSE), 0) -> 0 | G12: =IFERROR(VLOOKUP(Tabla1[[#This Row],[SISMED]],TblDisponibilidad[],11,FALSE), 0) -> 0 | H12: =IFERROR(VLOOKUP(Tabla1[[#This Row],[SISMED]],TblDisponibilidad[],12,FALSE), 0) -> 0 | I12: =IFERROR(VLOOKUP(Tabla1[[#This Row],[SISMED]],TblDisponibilidad[],13,FALSE), 0) -> 0 | J12: =IFERROR(VLOOKUP(Tabla1[[#This Row],[SISMED]],TblDisponibilidad[],14,FALSE), 0) -> 0 | K12: =IFERROR(VLOOKUP(Tabla1[[#This Row],[SISMED]],TblDisponibilidad[],15,FALSE), 0) -> 0 | L12: =IFERROR(VLOOKUP(Tabla1[[#This Row],[SISMED]],TblDisponibilidad[],16,FALSE), 0) -> 0 | M12: =IFERROR(VLOOKUP(Tabla1[[#This Row],[SISMED]],TblDisponibilidad[],17,FALSE), 0) -> 0 | N12: =IFERROR(VLOOKUP(Tabla1[[#This Row],[SISMED]],TblDisponibilidad[],18,FALSE), 0) -> 0 | O12: =IFERROR(VLOOKUP(Tabla1[[#This Row],[SISMED]],TblDisponibilidad[],19,FALSE), 0) -> 0 | P12: =IFERROR(VLOOKUP(Tabla1[[#This Row],[SISMED]],TblDisponibilidad[],20,FALSE), 0) -> 0 | Q12: =IFERROR(VLOOKUP(Tabla1[[#This Row],[SISMED]],TblDisponibilidad[],21,FALSE), 0) -> 0 | R12: =IFERROR(VLOOKUP(Tabla1[[#This Row],[SISMED]],TblDisponibilidad[],22,FALSE), 0) -> 0 | S12: =IFERROR(VLOOKUP(Tabla1[[#This Row],[SISMED]],TblDisponibilidad[],23,FALSE), 0) -> 0
A13: 00269 | B13: =IFERROR(VLOOKUP(Tabla1[[#This Row],[SISMED]],TblDisponibilidad[],2,FALSE), "") | C13: =IFERROR(VLOOKUP(Tabla1[[#This Row],[SISMED]],TblDisponibilidad[],7,FALSE), 0) -> 0 | D13: =IFERROR(VLOOKUP(Tabla1[[#This Row],[SISMED]],TblDisponibilidad[],8,FALSE), 0) -> 0 | E13: =IFERROR(VLOOKUP(Tabla1[[#This Row],[SISMED]],TblDisponibilidad[],9,FALSE), 0) -> 0 | F13: =IFERROR(VLOOKUP(Tabla1[[#This Row],[SISMED]],TblDisponibilidad[],10,FALSE), 0) -> 0 | G13: =IFERROR(VLOOKUP(Tabla1[[#This Row],[SISMED]],TblDisponibilidad[],11,FALSE), 0) -> 0 | H13: =IFERROR(VLOOKUP(Tabla1[[#This Row],[SISMED]],TblDisponibilidad[],12,FALSE), 0) -> 0 | I13: =IFERROR(VLOOKUP(Tabla1[[#This Row],[SISMED]],TblDisponibilidad[],13,FALSE), 0) -> 0 | J13: =IFERROR(VLOOKUP(Tabla1[[#This Row],[SISMED]],TblDisponibilidad[],14,FALSE), 0) -> 0 | K13: =IFERROR(VLOOKUP(Tabla1[[#This Row],[SISMED]],TblDisponibilidad[],15,FALSE), 0) -> 0 | L13: =IFERROR(VLOOKUP(Tabla1[[#This Row],[SISMED]],TblDisponibilidad[],16,FALSE), 0) -> 0 | M13: =IFERROR(VLOOKUP(Tabla1[[#This Row],[SISMED]],TblDisponibilidad[],17,FALSE), 0) -> 0 | N13: =IFERROR(VLOOKUP(Tabla1[[#This Row],[SISMED]],TblDisponibilidad[],18,FALSE), 0) -> 0 | O13: =IFERROR(VLOOKUP(Tabla1[[#This Row],[SISMED]],TblDisponibilidad[],19,FALSE), 0) -> 0 | P13: =IFERROR(VLOOKUP(Tabla1[[#This Row],[SISMED]],TblDisponibilidad[],20,FALSE), 0) -> 0 | Q13: =IFERROR(VLOOKUP(Tabla1[[#This Row],[SISMED]],TblDisponibilidad[],21,FALSE), 0) -> 0 | R13: =IFERROR(VLOOKUP(Tabla1[[#This Row],[SISMED]],TblDisponibilidad[],22,FALSE), 0) -> 0 | S13: =IFERROR(VLOOKUP(Tabla1[[#This Row],[SISMED]],TblDisponibilidad[],23,FALSE), 0) -> 0
A14: 00274 | B14: =IFERROR(VLOOKUP(Tabla1[[#This Row],[SISMED]],TblDisponibilidad[],2,FALSE), "") | C14: =IFERROR(VLOOKUP(Tabla1[[#This Row],[SISMED]],TblDisponibilidad[],7,FALSE), 0) -> 0 | D14: =IFERROR(VLOOKUP(Tabla1[[#This Row],[SISMED]],TblDisponibilidad[],8,FALSE), 0) -> 0 | E14: =IFERROR(VLOOKUP(Tabla1[[#This Row],[SISMED]],TblDisponibilidad[],9,FALSE), 0) -> 0 | F14: =IFERROR(VLOOKUP(Tabla1[[#This Row],[SISMED]],TblDisponibilidad[],10,FALSE), 0) -> 0 | G14: =IFERROR(VLOOKUP(Tabla1[[#This Row],[SISMED]],TblDisponibilidad[],11,FALSE), 0) -> 0 | H14: =IFERROR(VLOOKUP(Tabla1[[#This Row],[SISMED]],TblDisponibilidad[],12,FALSE), 0) -> 0 | I14: =IFERROR(VLOOKUP(Tabla1[[#This Row],[SISMED]],TblDisponibilidad[],13,FALSE), 0) -> 0 | J14: =IFERROR(VLOOKUP(Tabla1[[#This Row],[SISMED]],TblDisponibilidad[],14,FALSE), 0) -> 0 | K14: =IFERROR(VLOOKUP(Tabla1[[#This Row],[SISMED]],TblDisponibilidad[],15,FALSE), 0) -> 0 | L14: =IFERROR(VLOOKUP(Tabla1[[#This Row],[SISMED]],TblDisponibilidad[],16,FALSE), 0) -> 0 | M14: =IFERROR(VLOOKUP(Tabla1[[#This Row],[SISMED]],TblDisponibilidad[],17,FALSE), 0) -> 0 | N14: =IFERROR(VLOOKUP(Tabla1[[#This Row],[SISMED]],TblDisponibilidad[],18,FALSE), 0) -> 0 | O14: =IFERROR(VLOOKUP(Tabla1[[#This Row],[SISMED]],TblDisponibilidad[],19,FALSE), 0) -> 0 | P14: =IFERROR(VLOOKUP(Tabla1[[#This Row],[SISMED]],TblDisponibilidad[],20,FALSE), 0) -> 0 | Q14: =IFERROR(VLOOKUP(Tabla1[[#This Row],[SISMED]],TblDisponibilidad[],21,FALSE), 0) -> 0 | R14: =IFERROR(VLOOKUP(Tabla1[[#This Row],[SISMED]],TblDisponibilidad[],22,FALSE), 0) -> 0 | S14: =IFERROR(VLOOKUP(Tabla1[[#This Row],[SISMED]],TblDisponibilidad[],23,FALSE), 0) -> 0
... A895: 46886 | B895: =IFERROR(VLOOKUP(Tabla1[[#This Row],[SISMED]],TblDisponibilidad[],2,FALSE), "") | C895: =IFERROR(VLOOKUP(Tabla1[[#This Row],[SISMED]],TblDisponibilidad[],7,FALSE), 0) -> 0 | D895: =IFERROR(VLOOKUP(Tabla1[[#This Row],[SISMED]],TblDisponibilidad[],8,FALSE), 0) -> 0 | E895: =IFERROR(VLOOKUP(Tabla1[[#This Row],[SISMED]],TblDisponibilidad[],9,FALSE), 0) -> 0 | F895: =IFERROR(VLOOKUP(Tabla1[[#This Row],[SISMED]],TblDisponibilidad[],10,FALSE), 0) -> 0 | G895: =IFERROR(VLOOKUP(Tabla1[[#This Row],[SISMED]],TblDisponibilidad[],11,FALSE), 0) -> 0 | H895: =IFERROR(VLOOKUP(Tabla1[[#This Row],[SISMED]],TblDisponibilidad[],12,FALSE), 0) -> 0 | I895: =IFERROR(VLOOKUP(Tabla1[[#This Row],[SISMED]],TblDisponibilidad[],13,FALSE), 0) -> 0 | J895: =IFERROR(VLOOKUP(Tabla1[[#This Row],[SISMED]],TblDisponibilidad[],14,FALSE), 0) -> 0 | K895: =IFERROR(VLOOKUP(Tabla1[[#This Row],[SISMED]],TblDisponibilidad[],15,FALSE), 0) -> 0 | L895: =IFERROR(VLOOKUP(Tabla1[[#This Row],[SISMED]],TblDisponibilidad[],16,FALSE), 0) -> 0 | M895: =IFERROR(VLOOKUP(Tabla1[[#This Row],[SISMED]],TblDisponibilidad[],17,FALSE), 0) -> 0 | N895: =IFERROR(VLOOKUP(Tabla1[[#This Row],[SISMED]],TblDisponibilidad[],18,FALSE), 0) -> 0 | O895: =IFERROR(VLOOKUP(Tabla1[[#This Row],[SISMED]],TblDisponibilidad[],19,FALSE), 0) -> 0 | P895: =IFERROR(VLOOKUP(Tabla1[[#This Row],[SISMED]],TblDisponibilidad[],20,FALSE), 0) -> 0 | Q895: =IFERROR(VLOOKUP(Tabla1[[#This Row],[SISMED]],TblDisponibilidad[],21,FALSE), 0) -> 0 | R895: =IFERROR(VLOOKUP(Tabla1[[#This Row],[SISMED]],TblDisponibilidad[],22,FALSE), 0) -> 0 | S895: =IFERROR(VLOOKUP(Tabla1[[#This Row],[SISMED]],TblDisponibilidad[],23,FALSE), 0) -> 0

Sheet Disp UCI
R1: % para UCI | S1: =(COUNTIF(Tabla13[Estado],"no rota")+COUNTIF(Tabla13[Estado],"NORMO STOCK")+COUNTIF(Tabla13[Estado],"SOBRE STOCK"))/(COUNTIF(Tabla13[Estado],"<>solid")-COUNTBLANK(Tabla13[Estado])-COUNTIF(Tabla13[Estado],"no incluido")) -> 0
A2: SISMED | B2: PRODUCTO | C2: ago-21 | D2: sep-21 | E2: oct-21 | F2: nov-21 | G2: dic-21 | H2: ene-22 | I2: feb-22 | J2: mar-22 | K2: abr-22 | L2: may-22 | M2: jun-22 | N2: jul-22 | O2: CPMA SIS | P2: Meses Rotacion | Q2: Stock | R2: Meses Abastecidos | S2: Estado
A3: 00091 | B3: =IFERROR(VLOOKUP(Tabla13[[#This Row],[SISMED]],TblDisponibilidad[],2,FALSE), "") | C3: =IFERROR(VLOOKUP(Tabla13[[#This Row],[SISMED]],TblDisponibilidad[],7,FALSE), 0) -> 0 | D3: =IFERROR(VLOOKUP(Tabla13[[#This Row],[SISMED]],TblDisponibilidad[],8,FALSE), 0) -> 0 | E3: =IFERROR(VLOOKUP(Tabla13[[#This Row],[SISMED]],TblDisponibilidad[],9,FALSE), 0) -> 0 | F3: =IFERROR(VLOOKUP(Tabla13[[#This Row],[SISMED]],TblDisponibilidad[],10,FALSE), 0) -> 0 | G3: =IFERROR(VLOOKUP(Tabla13[[#This Row],[SISMED]],TblDisponibilidad[],11,FALSE), 0) -> 0 | H3: =IFERROR(VLOOKUP(Tabla13[[#This Row],[SISMED]],TblDisponibilidad[],12,FALSE), 0) -> 0 | I3: =IFERROR(VLOOKUP(Tabla13[[#This Row],[SISMED]],TblDisponibilidad[],13,FALSE), 0) -> 0 | J3: =IFERROR(VLOOKUP(Tabla13[[#This Row],[SISMED]],TblDisponibilidad[],14,FALSE), 0) -> 0 | K3: =IFERROR(VLOOKUP(Tabla13[[#This Row],[SISMED]],TblDisponibilidad[],15,FALSE), 0) -> 0 | L3: =IFERROR(VLOOKUP(Tabla13[[#This Row],[SISMED]],TblDisponibilidad[],16,FALSE), 0) -> 0 | M3: =IFERROR(VLOOKUP(Tabla13[[#This Row],[SISMED]],TblDisponibilidad[],17,FALSE), 0) -> 0 | N3: =IFERROR(VLOOKUP(Tabla13[[#This Row],[SISMED]],TblDisponibilidad[],18,FALSE), 0) -> 0 | O3: =IFERROR(VLOOKUP(Tabla13[[#This Row],[SISMED]],TblDisponibilidad[],19,FALSE), 0) -> 0 | P3: =IFERROR(VLOOKUP(Tabla13[[#This Row],[SISMED]],TblDisponibilidad[],20,FALSE), 0) -> 0 | Q3: =IFERROR(VLOOKUP(Tabla13[[#This Row],[SISMED]],TblDisponibilidad[],21,FALSE), 0) -> 0 | R3: =IFERROR(VLOOKUP(Tabla13[[#This Row],[SISMED]],TblDisponibilidad[],22,FALSE), 0) -> 0 | S3: =IFERROR(VLOOKUP(Tabla13[[#This Row],[SISMED]],TblDisponibilidad[],23,FALSE), 0) -> 0
A4: 00095 | B4: =IFERROR(VLOOKUP(Tabla13[[#This Row],[SISMED]],TblDisponibilidad[],2,FALSE), "") | C4: =IFERROR(VLOOKUP(Tabla13[[#This Row],[SISMED]],TblDisponibilidad[],7,FALSE), 0) -> 0 | D4: =IFERROR(VLOOKUP(Tabla13[[#This Row],[SISMED]],TblDisponibilidad[],8,FALSE), 0) -> 0 | E4: =IFERROR(VLOOKUP(Tabla13[[#This Row],[SISMED]],TblDisponibilidad[],9,FALSE), 0) -> 0 | F4: =IFERROR(VLOOKUP(Tabla13[[#This Row],[SISMED]],TblDisponibilidad[],10,FALSE), 0) -> 0 | G4: =IFERROR(VLOOKUP(Tabla13[[#This Row],[SISMED]],TblDisponibilidad[],11,FALSE), 0) -> 0 | H4: =IFERROR(VLOOKUP(Tabla13[[#This Row],[SISMED]],TblDisponibilidad[],12,FALSE), 0) -> 0 | I4: =IFERROR(VLOOKUP(Tabla13[[#This Row],[SISMED]],TblDisponibilidad[],13,FALSE), 0) -> 0 | J4: =IFERROR(VLOOKUP(Tabla13[[#This Row],[SISMED]],TblDisponibilidad[],14,FALSE), 0) -> 0 | K4: =IFERROR(VLOOKUP(Tabla13[[#This Row],[SISMED]],TblDisponibilidad[],15,FALSE), 0) -> 0 | L4: =IFERROR(VLOOKUP(Tabla13[[#This Row],[SISMED]],TblDisponibilidad[],16,FALSE), 0) -> 0 | M4: =IFERROR(VLOOKUP(Tabla13[[#This Row],[SISMED]],TblDisponibilidad[],17,FALSE), 0) -> 0 | N4: =IFERROR(VLOOKUP(Tabla13[[#This Row],[SISMED]],TblDisponibilidad[],18,FALSE), 0) -> 0 | O4: =IFERROR(VLOOKUP(Tabla13[[#This Row],[SISMED]],TblDisponibilidad[],19,FALSE), 0) -> 0 | P4: =IFERROR(VLOOKUP(Tabla13[[#This Row],[SISMED]],TblDisponibilidad[],20,FALSE), 0) -> 0 | Q4: =IFERROR(VLOOKUP(Tabla13[[#This Row],[SISMED]],TblDisponibilidad[],21,FALSE), 0) -> 0 | R4: =IFERROR(VLOOKUP(Tabla13[[#This Row],[SISMED]],TblDisponibilidad[],22,FALSE), 0) -> 0 | S4: =IFERROR(VLOOKUP(Tabla13[[#This Row],[SISMED]],TblDisponibilidad[],23,FALSE), 0) -> 0
A5: 00111 | B5: =IFERROR(VLOOKUP(Tabla13[[#This Row],[SISMED]],TblDisponibilidad[],2,FALSE), "") | C5: =IFERROR(VLOOKUP(Tabla13[[#This Row],[SISMED]],TblDisponibilidad[],7,FALSE), 0) -> 0 | D5: =IFERROR(VLOOKUP(Tabla13[[#This Row],[SISMED]],TblDisponibilidad[],8,FALSE), 0) -> 0 | E5: =IFERROR(VLOOKUP(Tabla13[[#This Row],[SISMED]],TblDisponibilidad[],9,FALSE), 0) -> 0 | F5: =IFERROR(VLOOKUP(Tabla13[[#This Row],[SISMED]],TblDisponibilidad[],10,FALSE), 0) -> 0 | G5: =IFERROR(VLOOKUP(Tabla13[[#This Row],[SISMED]],TblDisponibilidad[],11,FALSE), 0) -> 0 | H5: =IFERROR(VLOOKUP(Tabla13[[#This Row],[SISMED]],TblDisponibilidad[],12,FALSE), 0) -> 0 | I5: =IFERROR(VLOOKUP(Tabla13[[#This Row],[SISMED]],TblDisponibilidad[],13,FALSE), 0) -> 0 | J5: =IFERROR(VLOOKUP(Tabla13[[#This Row],[SISMED]],TblDisponibilidad[],14,FALSE), 0) -> 0 | K5: =IFERROR(VLOOKUP(Tabla13[[#This Row],[SISMED]],TblDisponibilidad[],15,FALSE), 0) -> 0 | L5: =IFERROR(VLOOKUP(Tabla13[[#This Row],[SISMED]],TblDisponibilidad[],16,FALSE), 0) -> 0 | M5: =IFERROR(VLOOKUP(Tabla13[[#This Row],[SISMED]],TblDisponibilidad[],17,FALSE), 0) -> 0 | N5: =IFERROR(VLOOKUP(Tabla13[[#This Row],[SISMED]],TblDisponibilidad[],18,FALSE), 0) -> 0 | O5: =IFERROR(VLOOKUP(Tabla13[[#This Row],[SISMED]],TblDisponibilidad[],19,FALSE), 0) -> 0 | P5: =IFERROR(VLOOKUP(Tabla13[[#This Row],[SISMED]],TblDisponibilidad[],20,FALSE), 0) -> 0 | Q5: =IFERROR(VLOOKUP(Tabla13[[#This Row],[SISMED]],TblDisponibilidad[],21,FALSE), 0) -> 0 | R5: =IFERROR(VLOOKUP(Tabla13[[#This Row],[SISMED]],TblDisponibilidad[],22,FALSE), 0) -> 0 | S5: =IFERROR(VLOOKUP(Tabla13[[#This Row],[SISMED]],TblDisponibilidad[],23,FALSE), 0) -> 0
A6: 00132 | B6: =IFERROR(VLOOKUP(Tabla13[[#This Row],[SISMED]],TblDisponibilidad[],2,FALSE), "") | C6: =IFERROR(VLOOKUP(Tabla13[[#This Row],[SISMED]],TblDisponibilidad[],7,FALSE), 0) -> 0 | D6: =IFERROR(VLOOKUP(Tabla13[[#This Row],[SISMED]],TblDisponibilidad[],8,FALSE), 0) -> 0 | E6: =IFERROR(VLOOKUP(Tabla13[[#This Row],[SISMED]],TblDisponibilidad[],9,FALSE), 0) -> 0 | F6: =IFERROR(VLOOKUP(Tabla13[[#This Row],[SISMED]],TblDisponibilidad[],10,FALSE), 0) -> 0 | G6: =IFERROR(VLOOKUP(Tabla13[[#This Row],[SISMED]],TblDisponibilidad[],11,FALSE), 0) -> 0 | H6: =IFERROR(VLOOKUP(Tabla13[[#This Row],[SISMED]],TblDisponibilidad[],12,FALSE), 0) -> 0 | I6: =IFERROR(VLOOKUP(Tabla13[[#This Row],[SISMED]],TblDisponibilidad[],13,FALSE), 0) -> 0 | J6: =IFERROR(VLOOKUP(Tabla13[[#This Row],[SISMED]],TblDisponibilidad[],14,FALSE), 0) -> 0 | K6: =IFERROR(VLOOKUP(Tabla13[[#This Row],[SISMED]],TblDisponibilidad[],15,FALSE), 0) -> 0 | L6: =IFERROR(VLOOKUP(Tabla13[[#This Row],[SISMED]],TblDisponibilidad[],16,FALSE), 0) -> 0 | M6: =IFERROR(VLOOKUP(Tabla13[[#This Row],[SISMED]],TblDisponibilidad[],17,FALSE), 0) -> 0 | N6: =IFERROR(VLOOKUP(Tabla13[[#This Row],[SISMED]],TblDisponibilidad[],18,FALSE), 0) -> 0 | O6: =IFERROR(VLOOKUP(Tabla13[[#This Row],[SISMED]],TblDisponibilidad[],19,FALSE), 0) -> 0 | P6: =IFERROR(VLOOKUP(Tabla13[[#This Row],[SISMED]],TblDisponibilidad[],20,FALSE), 0) -> 0 | Q6: =IFERROR(VLOOKUP(Tabla13[[#This Row],[SISMED]],TblDisponibilidad[],21,FALSE), 0) -> 0 | R6: =IFERROR(VLOOKUP(Tabla13[[#This Row],[SISMED]],TblDisponibilidad[],22,FALSE), 0) -> 0 | S6: =IFERROR(VLOOKUP(Tabla13[[#This Row],[SISMED]],TblDisponibilidad[],23,FALSE), 0) -> 0
A7: 00143 | B7: =IFERROR(VLOOKUP(Tabla13[[#This Row],[SISMED]],TblDisponibilidad[],2,FALSE), "") | C7: =IFERROR(VLOOKUP(Tabla13[[#This Row],[SISMED]],TblDisponibilidad[],7,FALSE), 0) -> 0 | D7: =IFERROR(VLOOKUP(Tabla13[[#This Row],[SISMED]],TblDisponibilidad[],8,FALSE), 0) -> 0 | E7: =IFERROR(VLOOKUP(Tabla13[[#This Row],[SISMED]],TblDisponibilidad[],9,FALSE), 0) -> 0 | F7: =IFERROR(VLOOKUP(Tabla13[[#This Row],[SISMED]],TblDisponibilidad[],10,FALSE), 0) -> 0 | G7: =IFERROR(VLOOKUP(Tabla13[[#This Row],[SISMED]],TblDisponibilidad[],11,FALSE), 0) -> 0 | H7: =IFERROR(VLOOKUP(Tabla13[[#This Row],[SISMED]],TblDisponibilidad[],12,FALSE), 0) -> 0 | I7: =IFERROR(VLOOKUP(Tabla13[[#This Row],[SISMED]],TblDisponibilidad[],13,FALSE), 0) -> 0 | J7: =IFERROR(VLOOKUP(Tabla13[[#This Row],[SISMED]],TblDisponibilidad[],14,FALSE), 0) -> 0 | K7: =IFERROR(VLOOKUP(Tabla13[[#This Row],[SISMED]],TblDisponibilidad[],15,FALSE), 0) -> 0 | L7: =IFERROR(VLOOKUP(Tabla13[[#This Row],[SISMED]],TblDisponibilidad[],16,FALSE), 0) -> 0 | M7: =IFERROR(VLOOKUP(Tabla13[[#This Row],[SISMED]],TblDisponibilidad[],17,FALSE), 0) -> 0 | N7: =IFERROR(VLOOKUP(Tabla13[[#This Row],[SISMED]],TblDisponibilidad[],18,FALSE), 0) -> 0 | O7: =IFERROR(VLOOKUP(Tabla13[[#This Row],[SISMED]],TblDisponibilidad[],19,FALSE), 0) -> 0 | P7: =IFERROR(VLOOKUP(Tabla13[[#This Row],[SISMED]],TblDisponibilidad[],20,FALSE), 0) -> 0 | Q7: =IFERROR(VLOOKUP(Tabla13[[#This Row],[SISMED]],TblDisponibilidad[],21,FALSE), 0) -> 0 | R7: =IFERROR(VLOOKUP(Tabla13[[#This Row],[SISMED]],TblDisponibilidad[],22,FALSE), 0) -> 0 | S7: =IFERROR(VLOOKUP(Tabla13[[#This Row],[SISMED]],TblDisponibilidad[],23,FALSE), 0) -> 0
A8: 00200 | B8: =IFERROR(VLOOKUP(Tabla13[[#This Row],[SISMED]],TblDisponibilidad[],2,FALSE), "") | C8: =IFERROR(VLOOKUP(Tabla13[[#This Row],[SISMED]],TblDisponibilidad[],7,FALSE), 0) -> 0 | D8: =IFERROR(VLOOKUP(Tabla13[[#This Row],[SISMED]],TblDisponibilidad[],8,FALSE), 0) -> 0 | E8: =IFERROR(VLOOKUP(Tabla13[[#This Row],[SISMED]],TblDisponibilidad[],9,FALSE), 0) -> 0 | F8: =IFERROR(VLOOKUP(Tabla13[[#This Row],[SISMED]],TblDisponibilidad[],10,FALSE), 0) -> 0 | G8: =IFERROR(VLOOKUP(Tabla13[[#This Row],[SISMED]],TblDisponibilidad[],11,FALSE), 0) -> 0 | H8: =IFERROR(VLOOKUP(Tabla13[[#This Row],[SISMED]],TblDisponibilidad[],12,FALSE), 0) -> 0 | I8: =IFERROR(VLOOKUP(Tabla13[[#This Row],[SISMED]],TblDisponibilidad[],13,FALSE), 0) -> 0 | J8: =IFERROR(VLOOKUP(Tabla13[[#This Row],[SISMED]],TblDisponibilidad[],14,FALSE), 0) -> 0 | K8: =IFERROR(VLOOKUP(Tabla13[[#This Row],[SISMED]],TblDisponibilidad[],15,FALSE), 0) -> 0 | L8: =IFERROR(VLOOKUP(Tabla13[[#This Row],[SISMED]],TblDisponibilidad[],16,FALSE), 0) -> 0 | M8: =IFERROR(VLOOKUP(Tabla13[[#This Row],[SISMED]],TblDisponibilidad[],17,FALSE), 0) -> 0 | N8: =IFERROR(VLOOKUP(Tabla13[[#This Row],[SISMED]],TblDisponibilidad[],18,FALSE), 0) -> 0 | O8: =IFERROR(VLOOKUP(Tabla13[[#This Row],[SISMED]],TblDisponibilidad[],19,FALSE), 0) -> 0 | P8: =IFERROR(VLOOKUP(Tabla13[[#This Row],[SISMED]],TblDisponibilidad[],20,FALSE), 0) -> 0 | Q8: =IFERROR(VLOOKUP(Tabla13[[#This Row],[SISMED]],TblDisponibilidad[],21,FALSE), 0) -> 0 | R8: =IFERROR(VLOOKUP(Tabla13[[#This Row],[SISMED]],TblDisponibilidad[],22,FALSE), 0) -> 0 | S8: =IFERROR(VLOOKUP(Tabla13[[#This Row],[SISMED]],TblDisponibilidad[],23,FALSE), 0) -> 0
A9: 00223 | B9: =IFERROR(VLOOKUP(Tabla13[[#This Row],[SISMED]],TblDisponibilidad[],2,FALSE), "") | C9: =IFERROR(VLOOKUP(Tabla13[[#This Row],[SISMED]],TblDisponibilidad[],7,FALSE), 0) -> 0 | D9: =IFERROR(VLOOKUP(Tabla13[[#This Row],[SISMED]],TblDisponibilidad[],8,FALSE), 0) -> 0 | E9: =IFERROR(VLOOKUP(Tabla13[[#This Row],[SISMED]],TblDisponibilidad[],9,FALSE), 0) -> 0 | F9: =IFERROR(VLOOKUP(Tabla13[[#This Row],[SISMED]],TblDisponibilidad[],10,FALSE), 0) -> 0 | G9: =IFERROR(VLOOKUP(Tabla13[[#This Row],[SISMED]],TblDisponibilidad[],11,FALSE), 0) -> 0 | H9: =IFERROR(VLOOKUP(Tabla13[[#This Row],[SISMED]],TblDisponibilidad[],12,FALSE), 0) -> 0 | I9: =IFERROR(VLOOKUP(Tabla13[[#This Row],[SISMED]],TblDisponibilidad[],13,FALSE), 0) -> 0 | J9: =IFERROR(VLOOKUP(Tabla13[[#This Row],[SISMED]],TblDisponibilidad[],14,FALSE), 0) -> 0 | K9: =IFERROR(VLOOKUP(Tabla13[[#This Row],[SISMED]],TblDisponibilidad[],15,FALSE), 0) -> 0 | L9: =IFERROR(VLOOKUP(Tabla13[[#This Row],[SISMED]],TblDisponibilidad[],16,FALSE), 0) -> 0 | M9: =IFERROR(VLOOKUP(Tabla13[[#This Row],[SISMED]],TblDisponibilidad[],17,FALSE), 0) -> 0 | N9: =IFERROR(VLOOKUP(Tabla13[[#This Row],[SISMED]],TblDisponibilidad[],18,FALSE), 0) -> 0 | O9: =IFERROR(VLOOKUP(Tabla13[[#This Row],[SISMED]],TblDisponibilidad[],19,FALSE), 0) -> 0 | P9: =IFERROR(VLOOKUP(Tabla13[[#This Row],[SISMED]],TblDisponibilidad[],20,FALSE), 0) -> 0 | Q9: =IFERROR(VLOOKUP(Tabla13[[#This Row],[SISMED]],TblDisponibilidad[],21,FALSE), 0) -> 0 | R9: =IFERROR(VLOOKUP(Tabla13[[#This Row],[SISMED]],TblDisponibilidad[],22,FALSE), 0) -> 0 | S9: =IFERROR(VLOOKUP(Tabla13[[#This Row],[SISMED]],TblDisponibilidad[],23,FALSE), 0) -> 0
A10: 00225 | B10: =IFERROR(VLOOKUP(Tabla13[[#This Row],[SISMED]],TblDisponibilidad[],2,FALSE), "") | C10: =IFERROR(VLOOKUP(Tabla13[[#This Row],[SISMED]],TblDisponibilidad[],7,FALSE), 0) -> 0 | D10: =IFERROR(VLOOKUP(Tabla13[[#This Row],[SISMED]],TblDisponibilidad[],8,FALSE), 0) -> 0 | E10: =IFERROR(VLOOKUP(Tabla13[[#This Row],[SISMED]],TblDisponibilidad[],9,FALSE), 0) -> 0 | F10: =IFERROR(VLOOKUP(Tabla13[[#This Row],[SISMED]],TblDisponibilidad[],10,FALSE), 0) -> 0 | G10: =IFERROR(VLOOKUP(Tabla13[[#This Row],[SISMED]],TblDisponibilidad[],11,FALSE), 0) -> 0 | H10: =IFERROR(VLOOKUP(Tabla13[[#This Row],[SISMED]],TblDisponibilidad[],12,FALSE), 0) -> 0 | I10: =IFERROR(VLOOKUP(Tabla13[[#This Row],[SISMED]],TblDisponibilidad[],13,FALSE), 0) -> 0 | J10: =IFERROR(VLOOKUP(Tabla13[[#This Row],[SISMED]],TblDisponibilidad[],14,FALSE), 0) -> 0 | K10: =IFERROR(VLOOKUP(Tabla13[[#This Row],[SISMED]],TblDisponibilidad[],15,FALSE), 0) -> 0 | L10: =IFERROR(VLOOKUP(Tabla13[[#This Row],[SISMED]],TblDisponibilidad[],16,FALSE), 0) -> 0 | M10: =IFERROR(VLOOKUP(Tabla13[[#This Row],[SISMED]],TblDisponibilidad[],17,FALSE), 0) -> 0 | N10: =IFERROR(VLOOKUP(Tabla13[[#This Row],[SISMED]],TblDisponibilidad[],18,FALSE), 0) -> 0 | O10: =IFERROR(VLOOKUP(Tabla13[[#This Row],[SISMED]],TblDisponibilidad[],19,FALSE), 0) -> 0 | P10: =IFERROR(VLOOKUP(Tabla13[[#This Row],[SISMED]],TblDisponibilidad[],20,FALSE), 0) -> 0 | Q10: =IFERROR(VLOOKUP(Tabla13[[#This Row],[SISMED]],TblDisponibilidad[],21,FALSE), 0) -> 0 | R10: =IFERROR(VLOOKUP(Tabla13[[#This Row],[SISMED]],TblDisponibilidad[],22,FALSE), 0) -> 0 | S10: =IFERROR(VLOOKUP(Tabla13[[#This Row],[SISMED]],TblDisponibilidad[],23,FALSE), 0) -> 0
A11: 00234 | B11: =IFERROR(VLOOKUP(Tabla13[[#This Row],[SISMED]],TblDisponibilidad[],2,FALSE), "") | C11: =IFERROR(VLOOKUP(Tabla13[[#This Row],[SISMED]],TblDisponibilidad[],7,FALSE), 0) -> 0 | D11: =IFERROR(VLOOKUP(Tabla13[[#This Row],[SISMED]],TblDisponibilidad[],8,FALSE), 0) -> 0 | E11: =IFERROR(VLOOKUP(Tabla13[[#This Row],[SISMED]],TblDisponibilidad[],9,FALSE), 0) -> 0 | F11: =IFERROR(VLOOKUP(Tabla13[[#This Row],[SISMED]],TblDisponibilidad[],10,FALSE), 0) -> 0 | G11: =IFERROR(VLOOKUP(Tabla13[[#This Row],[SISMED]],TblDisponibilidad[],11,FALSE), 0) -> 0 | H11: =IFERROR(VLOOKUP(Tabla13[[#This Row],[SISMED]],TblDisponibilidad[],12,FALSE), 0) -> 0 | I11: =IFERROR(VLOOKUP(Tabla13[[#This Row],[SISMED]],TblDisponibilidad[],13,FALSE), 0) -> 0 | J11: =IFERROR(VLOOKUP(Tabla13[[#This Row],[SISMED]],TblDisponibilidad[],14,FALSE), 0) -> 0 | K11: =IFERROR(VLOOKUP(Tabla13[[#This Row],[SISMED]],TblDisponibilidad[],15,FALSE), 0) -> 0 | L11: =IFERROR(VLOOKUP(Tabla13[[#This Row],[SISMED]],TblDisponibilidad[],16,FALSE), 0) -> 0 | M11: =IFERROR(VLOOKUP(Tabla13[[#This Row],[SISMED]],TblDisponibilidad[],17,FALSE), 0) -> 0 | N11: =IFERROR(VLOOKUP(Tabla13[[#This Row],[SISMED]],TblDisponibilidad[],18,FALSE), 0) -> 0 | O11: =IFERROR(VLOOKUP(Tabla13[[#This Row],[SISMED]],TblDisponibilidad[],19,FALSE), 0) -> 0 | P11: =IFERROR(VLOOKUP(Tabla13[[#This Row],[SISMED]],TblDisponibilidad[],20,FALSE), 0) -> 0 | Q11: =IFERROR(VLOOKUP(Tabla13[[#This Row],[SISMED]],TblDisponibilidad[],21,FALSE), 0) -> 0 | R11: =IFERROR(VLOOKUP(Tabla13[[#This Row],[SISMED]],TblDisponibilidad[],22,FALSE), 0) -> 0 | S11: =IFERROR(VLOOKUP(Tabla13[[#This Row],[SISMED]],TblDisponibilidad[],23,FALSE), 0) -> 0
A12: 00259 | B12: =IFERROR(VLOOKUP(Tabla13[[#This Row],[SISMED]],TblDisponibilidad[],2,FALSE), "") | C12: =IFERROR(VLOOKUP(Tabla13[[#This Row],[SISMED]],TblDisponibilidad[],7,FALSE), 0) -> 0 | D12: =IFERROR(VLOOKUP(Tabla13[[#This Row],[SISMED]],TblDisponibilidad[],8,FALSE), 0) -> 0 | E12: =IFERROR(VLOOKUP(Tabla13[[#This Row],[SISMED]],TblDisponibilidad[],9,FALSE), 0) -> 0 | F12: =IFERROR(VLOOKUP(Tabla13[[#This Row],[SISMED]],TblDisponibilidad[],10,FALSE), 0) -> 0 | G12: =IFERROR(VLOOKUP(Tabla13[[#This Row],[SISMED]],TblDisponibilidad[],11,FALSE), 0) -> 0 | H12: =IFERROR(VLOOKUP(Tabla13[[#This Row],[SISMED]],TblDisponibilidad[],12,FALSE), 0) -> 0 | I12: =IFERROR(VLOOKUP(Tabla13[[#This Row],[SISMED]],TblDisponibilidad[],13,FALSE), 0) -> 0 | J12: =IFERROR(VLOOKUP(Tabla13[[#This Row],[SISMED]],TblDisponibilidad[],14,FALSE), 0) -> 0 | K12: =IFERROR(VLOOKUP(Tabla13[[#This Row],[SISMED]],TblDisponibilidad[],15,FALSE), 0) -> 0 | L12: =IFERROR(VLOOKUP(Tabla13[[#This Row],[SISMED]],TblDisponibilidad[],16,FALSE), 0) -> 0 | M12: =IFERROR(VLOOKUP(Tabla13[[#This Row],[SISMED]],TblDisponibilidad[],17,FALSE), 0) -> 0 | N12: =IFERROR(VLOOKUP(Tabla13[[#This Row],[SISMED]],TblDisponibilidad[],18,FALSE), 0) -> 0 | O12: =IFERROR(VLOOKUP(Tabla13[[#This Row],[SISMED]],TblDisponibilidad[],19,FALSE), 0) -> 0 | P12: =IFERROR(VLOOKUP(Tabla13[[#This Row],[SISMED]],TblDisponibilidad[],20,FALSE), 0) -> 0 | Q12: =IFERROR(VLOOKUP(Tabla13[[#This Row],[SISMED]],TblDisponibilidad[],21,FALSE), 0) -> 0 | R12: =IFERROR(VLOOKUP(Tabla13[[#This Row],[SISMED]],TblDisponibilidad[],22,FALSE), 0) -> 0 | S12: =IFERROR(VLOOKUP(Tabla13[[#This Row],[SISMED]],TblDisponibilidad[],23,FALSE), 0) -> 0
A13: 00269 | B13: =IFERROR(VLOOKUP(Tabla13[[#This Row],[SISMED]],TblDisponibilidad[],2,FALSE), "") | C13: =IFERROR(VLOOKUP(Tabla13[[#This Row],[SISMED]],TblDisponibilidad[],7,FALSE), 0) -> 0 | D13: =IFERROR(VLOOKUP(Tabla13[[#This Row],[SISMED]],TblDisponibilidad[],8,FALSE), 0) -> 0 | E13: =IFERROR(VLOOKUP(Tabla13[[#This Row],[SISMED]],TblDisponibilidad[],9,FALSE), 0) -> 0 | F13: =IFERROR(VLOOKUP(Tabla13[[#This Row],[SISMED]],TblDisponibilidad[],10,FALSE), 0) -> 0 | G13: =IFERROR(VLOOKUP(Tabla13[[#This Row],[SISMED]],TblDisponibilidad[],11,FALSE), 0) -> 0 | H13: =IFERROR(VLOOKUP(Tabla13[[#This Row],[SISMED]],TblDisponibilidad[],12,FALSE), 0) -> 0 | I13: =IFERROR(VLOOKUP(Tabla13[[#This Row],[SISMED]],TblDisponibilidad[],13,FALSE), 0) -> 0 | J13: =IFERROR(VLOOKUP(Tabla13[[#This Row],[SISMED]],TblDisponibilidad[],14,FALSE), 0) -> 0 | K13: =IFERROR(VLOOKUP(Tabla13[[#This Row],[SISMED]],TblDisponibilidad[],15,FALSE), 0) -> 0 | L13: =IFERROR(VLOOKUP(Tabla13[[#This Row],[SISMED]],TblDisponibilidad[],16,FALSE), 0) -> 0 | M13: =IFERROR(VLOOKUP(Tabla13[[#This Row],[SISMED]],TblDisponibilidad[],17,FALSE), 0) -> 0 | N13: =IFERROR(VLOOKUP(Tabla13[[#This Row],[SISMED]],TblDisponibilidad[],18,FALSE), 0) -> 0 | O13: =IFERROR(VLOOKUP(Tabla13[[#This Row],[SISMED]],TblDisponibilidad[],19,FALSE), 0) -> 0 | P13: =IFERROR(VLOOKUP(Tabla13[[#This Row],[SISMED]],TblDisponibilidad[],20,FALSE), 0) -> 0 | Q13: =IFERROR(VLOOKUP(Tabla13[[#This Row],[SISMED]],TblDisponibilidad[],21,FALSE), 0) -> 0 | R13: =IFERROR(VLOOKUP(Tabla13[[#This Row],[SISMED]],TblDisponibilidad[],22,FALSE), 0) -> 0 | S13: =IFERROR(VLOOKUP(Tabla13[[#This Row],[SISMED]],TblDisponibilidad[],23,FALSE), 0) -> 0
A14: 00274 | B14: =IFERROR(VLOOKUP(Tabla13[[#This Row],[SISMED]],TblDisponibilidad[],2,FALSE), "") | C14: =IFERROR(VLOOKUP(Tabla13[[#This Row],[SISMED]],TblDisponibilidad[],7,FALSE), 0) -> 0 | D14: =IFERROR(VLOOKUP(Tabla13[[#This Row],[SISMED]],TblDisponibilidad[],8,FALSE), 0) -> 0 | E14: =IFERROR(VLOOKUP(Tabla13[[#This Row],[SISMED]],TblDisponibilidad[],9,FALSE), 0) -> 0 | F14: =IFERROR(VLOOKUP(Tabla13[[#This Row],[SISMED]],TblDisponibilidad[],10,FALSE), 0) -> 0 | G14: =IFERROR(VLOOKUP(Tabla13[[#This Row],[SISMED]],TblDisponibilidad[],11,FALSE), 0) -> 0 | H14: =IFERROR(VLOOKUP(Tabla13[[#This Row],[SISMED]],TblDisponibilidad[],12,FALSE), 0) -> 0 | I14: =IFERROR(VLOOKUP(Tabla13[[#This Row],[SISMED]],TblDisponibilidad[],13,FALSE), 0) -> 0 | J14: =IFERROR(VLOOKUP(Tabla13[[#This Row],[SISMED]],TblDisponibilidad[],14,FALSE), 0) -> 0 | K14: =IFERROR(VLOOKUP(Tabla13[[#This Row],[SISMED]],TblDisponibilidad[],15,FALSE), 0) -> 0 | L14: =IFERROR(VLOOKUP(Tabla13[[#This Row],[SISMED]],TblDisponibilidad[],16,FALSE), 0) -> 0 | M14: =IFERROR(VLOOKUP(Tabla13[[#This Row],[SISMED]],TblDisponibilidad[],17,FALSE), 0) -> 0 | N14: =IFERROR(VLOOKUP(Tabla13[[#This Row],[SISMED]],TblDisponibilidad[],18,FALSE), 0) -> 0 | O14: =IFERROR(VLOOKUP(Tabla13[[#This Row],[SISMED]],TblDisponibilidad[],19,FALSE), 0) -> 0 | P14: =IFERROR(VLOOKUP(Tabla13[[#This Row],[SISMED]],TblDisponibilidad[],20,FALSE), 0) -> 0 | Q14: =IFERROR(VLOOKUP(Tabla13[[#This Row],[SISMED]],TblDisponibilidad[],21,FALSE), 0) -> 0 | R14: =IFERROR(VLOOKUP(Tabla13[[#This Row],[SISMED]],TblDisponibilidad[],22,FALSE), 0) -> 0 | S14: =IFERROR(VLOOKUP(Tabla13[[#This Row],[SISMED]],TblDisponibilidad[],23,FALSE), 0) -> 0
... A895: 46886 | B895: =IFERROR(VLOOKUP(Tabla13[[#This Row],[SISMED]],TblDisponibilidad[],2,FALSE), "") | C895: =IFERROR(VLOOKUP(Tabla13[[#This Row],[SISMED]],TblDisponibilidad[],7,FALSE), 0) -> 0 | D895: =IFERROR(VLOOKUP(Tabla13[[#This Row],[SISMED]],TblDisponibilidad[],8,FALSE), 0) -> 0 | E895: =IFERROR(VLOOKUP(Tabla13[[#This Row],[SISMED]],TblDisponibilidad[],9,FALSE), 0) -> 0 | F895: =IFERROR(VLOOKUP(Tabla13[[#This Row],[SISMED]],TblDisponibilidad[],10,FALSE), 0) -> 0 | G895: =IFERROR(VLOOKUP(Tabla13[[#This Row],[SISMED]],TblDisponibilidad[],11,FALSE), 0) -> 0 | H895: =IFERROR(VLOOKUP(Tabla13[[#This Row],[SISMED]],TblDisponibilidad[],12,FALSE), 0) -> 0 | I895: =IFERROR(VLOOKUP(Tabla13[[#This Row],[SISMED]],TblDisponibilidad[],13,FALSE), 0) -> 0 | J895: =IFERROR(VLOOKUP(Tabla13[[#This Row],[SISMED]],TblDisponibilidad[],14,FALSE), 0) -> 0 | K895: =IFERROR(VLOOKUP(Tabla13[[#This Row],[SISMED]],TblDisponibilidad[],15,FALSE), 0) -> 0 | L895: =IFERROR(VLOOKUP(Tabla13[[#This Row],[SISMED]],TblDisponibilidad[],16,FALSE), 0) -> 0 | M895: =IFERROR(VLOOKUP(Tabla13[[#This Row],[SISMED]],TblDisponibilidad[],17,FALSE), 0) -> 0 | N895: =IFERROR(VLOOKUP(Tabla13[[#This Row],[SISMED]],TblDisponibilidad[],18,FALSE), 0) -> 0 | O895: =IFERROR(VLOOKUP(Tabla13[[#This Row],[SISMED]],TblDisponibilidad[],19,FALSE), 0) -> 0 | P895: =IFERROR(VLOOKUP(Tabla13[[#This Row],[SISMED]],TblDisponibilidad[],20,FALSE), 0) -> 0 | Q895: =IFERROR(VLOOKUP(Tabla13[[#This Row],[SISMED]],TblDisponibilidad[],21,FALSE), 0) -> 0 | R895: =IFERROR(VLOOKUP(Tabla13[[#This Row],[SISMED]],TblDisponibilidad[],22,FALSE), 0) -> 0 | S895: =IFERROR(VLOOKUP(Tabla13[[#This Row],[SISMED]],TblDisponibilidad[],23,FALSE), 0) -> 0

Sheet Medicamentos
A1: Tipo | B1: (Varios elementos)
A2: LISTA DE MEDICAMENTOS | E2: % de disponibilidad de medicamentos | F2: =((COUNTIF(F4:F600,"NORMO STOCK"))+(COUNTIF(F4:F600,"SOBRE STOCK")))/(((COUNTIF(F4:F600,"<>solid"))-(COUNTIF(F4:F600,"=No Rota"))-(COUNTBLANK(F4:F600)))) -> 0.64133739
A3: Etiquetas de fila | B3: Descripción | C3: Concentración | D3: Presentación | E3: Forma Farmacéutica | F3: Estado
A4: 00091 | B4: ACIDO ACETILSALICILICO | C4: 100 mg | D4: TABLETA | F4: NORMO STOCK
A5: 00132 | B5: ACICLOVIR (COMO SAL SODICA) | C5: 250 mg | D5: INYECTABLE | E5: 10 mL | F5: No Rota
A6: 00143 | B6: ACICLOVIR | C6: 200 mg | D6: TABLETA | F6: NORMO STOCK
A7: 00200 | B7: ACIDO FOLICO | C7: 500 µg (0.5 mg) | D7: TABLETA | F7: NORMO STOCK
A8: 00223 | B8: ACIDO TRANEXAMICO | C8: 1 g | D8: INYECTABLE | E8: 10 mL | F8: SUB STOCK
A9: 00225 | B9: ACIDO TRANEXAMICO | C9: 250 mg | D9: TABLETA | F9: SUB STOCK
A10: 00226 | B10: ACIDO URSODEOXICOLICO | C10: 250 mg | D10: TABLETA | F10: No Rota
A11: 00234 | B11: ADENOSINA | C11: 6 mg/2 mL | D11: INYECTABLE | E11: 2 mL | F11: SOBRE STOCK
A12: 00259 | B12: ALBENDAZOL | C12: 100 mg/5 mL | D12: SUSPENSION | E12: 20 mL | F12: DESABASTECIDO
A13: 00269 | B13: ALBENDAZOL | C13: 200 mg | D13: TABLETA | F13: SOBRE STOCK
A14: 00274 | B14: ALBUMINA HUMANA | C14: 20 g/100 mL | D14: INYECTABLE | E14: 50 mL | F14: SUB STOCK
A15: 00393 | B15: ALPRAZOLAM | C15: 500 µg (0.5 mg) | D15: TABLETA | F15: SUB STOCK
A16: 00396 | B16: ALPROSTADIL | C16: 500 µg/mL | D16: INYECTABLE | E16: 1 mL | F16: SUB STOCK
A17: 00620 | B17: AMFOTERICINA B | C17: 50 mg | D17: INYECTABLE | E17: 10 mL | F17: SOBRE STOCK
A18: 00625 | B18: AMIKACINA (COMO SULFATO) | C18: 50 mg/mL | D18: INYECTABLE | E18: 2 mL | F18: SUB STOCK
A19: 00627 | B19: AMIKACINA (COMO SULFATO) | C19: 250 mg/ mL | D19: INYECTABLE | E19: 2 mL | F19: SOBRE STOCK
A20: 00638 | B20: AMINOACIDOS | C20: 10 % | D20: INYECTABLE | E20: 250 mL | F20: SUB STOCK
A21: 00639 | B21: AMINOACIDOS | C21: 10 % | D21: INYECTABLE | E21: 500 mL | F21: SUB STOCK
A22: 00662 | B22: AMINOFILINA | C22: 25 mg/mL | D22: INYECTABLE | E22: 10 mL | F22: No Rota
A23: 00663 | B23: AMIODARONA CLORHIDRATO | C23: 50 mg/mL | D23: INYECTABLE | E23: 3 mL | F23: NORMO STOCK
A24: 00671 | B24: AMLODIPINO (COMO BESILATO) | C24: 10 mg | D24: TABLETA | F24: SUB STOCK
A25: 00673 | B25: AMLODIPINO (COMO BESILATO) | C25: 5 mg | D25: TABLETA | F25: NORMO STOCK
A26: 00725 | B26: AMOXICILINA + ACIDO CLAVULANICO (COMO SAL POTASICA) | C26: 250 mg + 62.5 mg/5 mL | D26: SUSPENSION | E26: 60 mL | F26: SUB STOCK
A27: 00750 | B27: AMOXICILINA + ACIDO CLAVULANICO (COMO SAL POTASICA) | C27: 500 mg + 125 mg | D27: TABLETA | F27: SUB STOCK
A28: 00786 | B28: AMOXICILINA | C28: 250 mg/5 mL | D28: SUSPENSION | E28: 120 mL | F28: SOBRE STOCK
A29: 00794 | B29: AMOXICILINA | C29: 250 mg/5 mL | D29: SUSPENSION | E29: 60 mL | F29: SOBRE STOCK
A30: 00808 | B30: AMOXICILINA | C30: 500 mg | D30: TABLETA | F30: SOBRE STOCK
A31: 00822 | B31: AMPICILINA (COMO SAL SODICA) + SULBACTAM (COMO SAL SODICA) | C31: 1 g + 500 mg | D31: INYECTABLE | F31: SOBRE STOCK
A32: 00830 | B32: AMPICILINA SODICA | C32: 1 g | D32: INYECTABLE | F32: SOBRE STOCK
A33: 00900 | B33: ATENOLOL | C33: 100 mg | D33: TABLETA | F33: SOBRE STOCK
A34: 00903 | B34: ATORVASTATINA (COMO SAL CALCICA) | C34: 20 mg | D34: TABLETA | F34: NORMO STOCK
A35: 00904 | B35: ATORVASTATINA (COMO SAL CALCICA) | C35: 40 mg | D35: TABLETA | F35: NORMO STOCK
A36: 00909 | B36: ATROPINA SULFATO | C36: 500 µg/mL (0.5 mg/mL) | D36: INYECTABLE | E36: 1 mL | F36: SOBRE STOCK
A37: 00910 | B37: ATROPINA SULFATO | C37: 1 mg/mL | D37: INYECTABLE | E37: 1 mL | F37: SUB STOCK
A38: 00914 | B38: ATROPINA SULFATO (SOLUCION OFTALMICA) | C38: 10 mg/mL (1 %) | D38: SOLUCION | E38: 5 mL | F38: No Rota
A39: 00939 | B39: AZITROMICINA | C39: 200 mg/5 mL | D39: SUSPENSION | E39: 60 mL | F39: NORMO STOCK
A40: 00946 | B40: AZITROMICINA | C40: 250 mg | D40: TABLETA | F40: DESABASTECIDO
...

Sheet Material Medico
A1: Tipo | B1: (Varios elementos)
A2: LISTA DE MEDICAMENTOS | E2: % de disponibilidad de medicamentos | F2: =((COUNTIF(F4:F600,"NORMO STOCK"))+(COUNTIF(F4:F600,"SOBRE STOCK")))/(((COUNTIF(F4:F600,"<>solid"))-(COUNTIF(F4:F600,"=No Rota"))-(COUNTBLANK(F4:F600)))) -> 0.60649819
A3: Etiquetas de fila | B3: Descripción | C3: Concentración | D3: Presentación | E3: Forma Farmacéutica | F3: Estado
A4: 08054 | B4: PRESERVATIVOS SIN NONOXINOL | D4: UNIDAD | F4: NORMO STOCK
A5: 08068 | B5: DISPOSITIVO INTRAUTERINO DE COBRE | D5: UNIDAD | F5: SOBRE STOCK
A6: 10145 | B6: AGUJA HIPODERMICA DESCARTABLE N° 18 G X 1 1/2" | D6: UNIDAD | F6: NORMO STOCK
A7: 10148 | B7: AGUJA HIPODERMICA DESCARTABLE N° 20 G X 1" | D7: UNIDAD | F7: SUB STOCK
A8: 10155 | B8: AGUJA HIPODERMICA DESCARTABLE N° 23 G X 1" | D8: UNIDAD | F8: SUB STOCK
A9: 10230 | B9: ALCOHOL ETILICO (ETANOL) | C9: 96° | D9: SOLUCION | E9: 1 L | F9: SOBRE STOCK
A10: 10244 | B10: ALGODON HIDROFILO | D10: UNIDAD | E10: 100 g | F10: NORMO STOCK
A11: 10246 | B11: ALGODON HIDROFILO | D11: UNIDAD | E11: 25 g | F11: SOBRE STOCK
A12: 10248 | B12: ALGODON HIDROFILO | D12: UNIDAD | E12: 50 g | F12: SOBRE STOCK
A13: 10249 | B13: ALGODON HIDROFILO | D13: UNIDAD | E13: 500 g | F13: NORMO STOCK
A14: 10256 | B14: ALITA DESCARTABLE N° 21 G X 3/4" | D14: UNIDAD | F14: NORMO STOCK
A15: 10299 | B15: APOSITO TRANSPARENTE ADHESIVO 10 cm X 12 cm | D15: UNIDAD | F15: DESABASTECIDO
A16: 10302 | B16: APOSITO TRANSPARENTE ADHESIVO 6 cm X 7 cm | D16: UNIDAD | F16: SUB STOCK
A17: 10355 | B17: BOLSA COLECTORA DE ORINA X 100 mL | D17: UNIDAD | F17: SOBRE STOCK
A18: 10363 | B18: BOLSA COLECTORA DE ORINA X 2 L | D18: UNIDAD | F18: SUB STOCK
A19: 10367 | B19: BOLSA DE COLOSTOMIA ADULTO | D19: UNIDAD | F19: SOBRE STOCK
A20: 10369 | B20: BOLSA DE NUTRICION PARENTERAL 1 L | D20: UNIDAD | F20: SOBRE STOCK
A21: 10370 | B21: BOLSA PARA NUTRICION PARENTERAL X 3 L | D21: UNIDAD | F21: No Rota
A22: 10372 | B22: BOLSA DE TRANSFERENCIA DE PLASMA 300 mL | D22: UNIDAD | F22: NORMO STOCK
A23: 10386 | B23: BRAZALETE DE IDENTIFICACION PARA RECIEN NACIDO (BLANCO) | D23: UNIDAD | F23: NORMO STOCK
A24: 10419 | B24: CANULA BINASAL PARA OXIGENO PEDIATRICO | D24: UNIDAD | F24: NORMO STOCK
A25: 10428 | B25: CANULA PARA TRAQUEOSTOMIA Nº 8 | D25: UNIDAD | F25: No Rota
... A67: 17013 | B67: SONDA DE ASPIRACION ENDOTRAQUEAL CIRCUITO CERRADO Nº 14 | D67: UNIDAD | F67: SUB STOCK
A68: 17029 | B68: SONDA VESICAL | C68: 2 VIAS DESCARTABLE | D68: UNIDAD | E68: Nº 14 | F68: NORMO STOCK
A69: 17030 | B69: SONDA VESICAL | C69: 2 VIAS DESCARTABLE | D69: UNIDAD | E69: Nº 16 | F69: NORMO STOCK
A70: 17045 | B70: SONDA VESICAL | C70: 3 VIAS DESCARTABLE | D70: UNIDAD | E70: Nº 16 | F70: SOBRE STOCK
A71: 17049 | B71: SONDA VESICAL | C71: 3 VIAS DESCARTABLE | D71: UNIDAD | E71: Nº 18 CON BALON 50 mL | F71: No Rota
A72: 17074 | B72: SONDA NASOGASTRICA Nº 14 | D72: UNIDAD | F72: SOBRE STOCK
A73: 17075 | B73: SONDA NASOGASTRICA Nº 16 | D73: UNIDAD | F73: SOBRE STOCK
A74: 17083 | B74: SONDA VESICAL TIPO NELATON | D74: UNIDAD | E74: N° 14 | F74: SUB STOCK
A75: 17090 | B75: SONDA VESICAL TIPO NELATON | D75: UNIDAD | E75: Nº 12 | F75: SOBRE STOCK
A76: 18225 | B76: EQUIPO MICROGOTERO CON CAMARA GRADUADA 150 mL | D76: UNIDAD | F76: DESABASTECIDO
A77: 18326 | B77: BOLSA DE NUTRICION PARENTERAL 250 mL | D77: UNIDAD | F77: SUB STOCK
A78: 18327 | B78: BOLSA PARA NUTRICION PARENTERAL X 500 mL | D78: UNIDAD | F78: SOBRE STOCK
A79: 18381 | B79: APOSITO DE GASA Y ALGODON ESTERIL 10 cm X 20 cm | D79: UNIDAD | F79: SOBRE STOCK
A80: 18522 | B80: APOSITO DE GASA Y ALGODON ESTERIL 10 cm X 10 cm | D80: UNIDAD | F80: SOBRE STOCK
A81: 18940 | B81: COMPRESA DE GASA QUIRURGICA 48 cm X 48 cm | D81: UNIDAD | F81: SUB STOCK
...

Sheet SOP
A1: TRAZADORES DE SALA DE OPERACIONES | E1: % de disponibilidad de medicamentos esenciales | F1: =((COUNTIF(F3:F33,"SOBRE STOCK"))+(COUNTIF(F3:F33,"NORMO STOCK")))/(COUNTIF(F3:F33,"<>solid")-(COUNTIF(F3:F33,"No Rota"))-(COUNTIF(F3:F33,"No Manejado"))) -> #DIV/0!
A2: SISMED | B2: DESCRIPCION DEL MEDICAMENTOS | C2: CONCENTRACION | D2: PRESENTACION | E2: FORMA FARMACEUTICA | F2: ESTADO
A3: 00223 | B3: ACIDO TRANEXAMICO | C3: 1 g | D3: INYECTABLE | E3: 10 mL | F3: =IFERROR(VLOOKUP(A3,TblDisponibilidad[],23,FALSE),"No Manejado") -> No Manejado
A4: 00909 | B4: ATROPINA SULFATO | C4: 500 µg/mL (0.5 mg/mL) | D4: INYECTABLE | E4: 1 mL | F4: =IFERROR(VLOOKUP(A4,TblDisponibilidad[],23,FALSE),"No Manejado") -> No Manejado
A5: 01344 | B5: BROMURO DE ROCURONIO | C5: 10 mg/mL | D5: INYECTABLE | E5: 5 mL | F5: =IFERROR(VLOOKUP(A5,TblDisponibilidad[],23,FALSE),"No Manejado") -> No Manejado
A6: 01378 | B6: BUPIVACAINA CLORHIDRATO (SIN PRESERVANTES) | C6: 5 mg/mL (0.5 %) | D6: INYECTABLE | E6: 20 mL | F6: =IFERROR(VLOOKUP(A6,TblDisponibilidad[],23,FALSE),"No Manejado") -> No Manejado
A7: 19239 | B7: BUPIVACAINA CLORHIDRATO + DEXTROSA | C7: 20 mg + 320 mg | D7: INYECTABLE | E7: 4 mL | F7: =IFERROR(VLOOKUP(A7,TblDisponibilidad[],23,FALSE),"No Manejado") -> No Manejado
A8: 01639 | B8: CEFAZOLINA (COMO SAL SODICA) | C8: 1 g | D8: INYECTABLE | F8: =IFERROR(VLOOKUP(A8,TblDisponibilidad[],23,FALSE),"No Manejado") -> No Manejado
A9: 01684 | B9: CEFTRIAXONA SODICA | C9: 1 g | D9: INYECTABLE | F9: =IFERROR(VLOOKUP(A9,TblDisponibilidad[],23,FALSE),"No Manejado") -> No Manejado
A10: 02269 | B10: CLORURO DE SUXAMETONIO | C10: 50 mg/mL | D10: INYECTABLE | E10: 10 mL | F10: =IFERROR(VLOOKUP(A10,TblDisponibilidad[],23,FALSE),"No Manejado") -> No Manejado
A11: 02642 | B11: DEXAMETASONA FOSFATO (COMO SAL SODICA) | C11: 4 mg/2 mL | D11: INYECTABLE | E11: 2 mL | F11: =IFERROR(VLOOKUP(A11,TblDisponibilidad[],23,FALSE),"No Manejado") -> No Manejado
A12: 03139 | B12: ERGOMETRINA MALEATO | C12: 200 µg/mL (0.2 mg/mL) | D12: INYECTABLE | E12: 1 mL | F12: =IFERROR(VLOOKUP(A12,TblDisponibilidad[],23,FALSE),"No Manejado") -> No Manejado
A13: 03317 | B13: ETILEFRINA | C13: 10 mg/mL | D13: INYECTABLE | E13: 1 mL | F13: =IFERROR(VLOOKUP(A13,TblDisponibilidad[],23,FALSE),"No Manejado") -> No Manejado
A14: 03501 | B14: FENTANILO | C14: 50 µg/mL | D14: INYECTABLE | E14: 10 mL | F14: =IFERROR(VLOOKUP(A14,TblDisponibilidad[],23,FALSE),"No Manejado") -> No Manejado
A15: 26362 | B15: HIDROCORTISONA (COMO SUCCINATO SODICO) | C15: 100 mg | D15: INYECTABLE | F15: =IFERROR(VLOOKUP(A15,TblDisponibilidad[],23,FALSE),"No Manejado") -> No Manejado
A16: 04187 | B16: KETAMINA (COMO CLORHIDRATO) | C16: 50 mg/mL | D16: INYECTABLE | E16: 10 mL | F16: =IFERROR(VLOOKUP(A16,TblDisponibilidad[],23,FALSE),"No Manejado") -> No Manejado
A17: 04398 | B17: LIDOCAINA CLORHIDRATO + EPINEFRINA | C17: 20 mg + 10 ug/mL | D17: INYECTABLE | E17: 20 mL | F17: =IFERROR(VLOOKUP(A17,TblDisponibilidad[],23,FALSE),"No Manejado") -> No Manejado
A18: 04390 | B18: LIDOCAINA CLORHIDRATO SIN PRESERVANTES | C18: 2 g/100 mL (2 %) | D18: INYECTABLE | E18: 20 mL | F18: =IFERROR(VLOOKUP(A18,TblDisponibilidad[],23,FALSE),"No Manejado") -> No Manejado
A19: 04677 | B19: METAMIZOL SODICO | C19: 1 g | D19: INYECTABLE | E19: 2 mL | F19: =IFERROR(VLOOKUP(A19,TblDisponibilidad[],23,FALSE),"No Manejado") -> No Manejado
A20: 04743 | B20: METOCLOPRAMIDA CLORHIDRATO | C20: 5 mg/mL | D20: INYECTABLE | E20: 2 mL | F20: =IFERROR(VLOOKUP(A20,TblDisponibilidad[],23,FALSE),"No Manejado") -> No Manejado
A21: 04831 | B21: MIDAZOLAM | C21: 5 mg | D21: INYECTABLE | E21: 5 mL | F21: =IFERROR(VLOOKUP(A21,TblDisponibilidad[],23,FALSE),"No Manejado") -> No Manejado
A22: 04847 | B22: MISOPROSTOL | C22: 200 µg | D22: TABLETA | F22: =IFERROR(VLOOKUP(A22,TblDisponibilidad[],23,FALSE),"No Manejado") -> No Manejado
A23: 04900 | B23: MORFINA (CLORHIDRATO) | C23: 10 mg | D23: INYECTABLE | E23: 1 mL | F23: =IFERROR(VLOOKUP(A23,TblDisponibilidad[],23,FALSE),"No Manejado") -> No Manejado
A24: 05009 | B24: NEOSTIGMINA METILSULFATO | C24: 500 µg/mL | D24: INYECTABLE | E24: 1 mL | F24: =IFERROR(VLOOKUP(A24,TblDisponibilidad[],23,FALSE),"No Manejado") -> No Manejado
A25: 05157 | B25: ONDANSETRON (COMO CLORHIDRATO) | C25: 2 mg/mL | D25: INYECTABLE | E25: 4 mL | F25: =IFERROR(VLOOKUP(A25,TblDisponibilidad[],23,FALSE),"No Manejado") -> No Manejado
A26: 05253 | B26: OXITOCINA | C26: 10 UI | D26: INYECTABLE | E26: 1 mL | F26: =IFERROR(VLOOKUP(A26,TblDisponibilidad[],23,FALSE),"No Manejado") -> No Manejado
A27: 05408 | B27: PETIDINA CLORHIDRATO | C27: 50 mg/mL | D27: INYECTABLE | E27: 2 mL | F27: =IFERROR(VLOOKUP(A27,TblDisponibilidad[],23,FALSE),"No Manejado") -> No Manejado
A28: 19166 | B28: GELATINA SUCCINILATADA | C28: 4 g/100 mL | D28: INYECTABLE | E28: 500 mL | F28: =IFERROR(VLOOKUP(A28,TblDisponibilidad[],23,FALSE),"No Manejado") -> No Manejado
A29: 05626 | B29: PROPOFOL | C29: 10 mg/mL (1 %) | D29: INYECTABLE | E29: 20 mL | F29: =IFERROR(VLOOKUP(A29,TblDisponibilidad[],23,FALSE),"No Manejado") -> No Manejado
A30: 05658 | B30: RANITIDINA (COMO CLORHIDRATO) | C30: 25 mg/mL | D30: INYECTABLE | E30: 2 mL | F30: =IFERROR(VLOOKUP(A30,TblDisponibilidad[],23,FALSE),"No Manejado") -> No Manejado
A31: 05809 | B31: SEVOFLURANO | C31: 100 mL/100 mL | D31: SOLUCION | E31: 250 mL | F31: =IFERROR(VLOOKUP(A31,TblDisponibilidad[],23,FALSE),"No Manejado") -> No Manejado
A32: 05873 | B32: SODIO CLORURO | C32: 900 mg/100 mL (0.9 %) | D32: INYECTABLE | E32: 1 L | F32: =IFERROR(VLOOKUP(A32,TblDisponibilidad[],23,FALSE),"No Manejado") -> No Manejado
A33: 06231 | B33: TRAMADOL CLORHIDRATO | C33: 50 mg/mL | D33: INYECTABLE | E33: 1 mL | F33: =IFERROR(VLOOKUP(A33,TblDisponibilidad[],23,FALSE),"No Manejado") -> No Manejado

Sheet Medicamento. Estrategia
A1: LISTA DE MEDICAMENTOS ESTRATEGIA | E1: % de disponibilidad de medicamentos esenciales | F1: =((COUNTIF(F3:F29,"SOBRE STOCK"))+(COUNTIF(F3:F29,"NORMO STOCK")))/(COUNTIF(F3:F29,"<>solid")-(COUNTIF(F3:F29,"No Rota"))-(COUNTIF(F3:F29,"No Manejado"))) -> #DIV/0!
A2: SISMED | B2: DESCRIPCION DEL MEDICAMENTOS | C2: CONCENTRACION | D2: PRESENTACION | E2: FORMA FARMACEUTICA | F2: ESTADO
A3: 38085 | B3: ATAZANAVIR + RITONAVIR | C3: 300 mg + 100 mg | E3: TABLETA | F3: =IFERROR(VLOOKUP(A3,TblDisponibilidad[],23,FALSE),"No Manejado") -> No Manejado
A4: 41842 | B4: DOLUTEGRAVIR + LAMIVUDINA + TENOFOVIR | C4: 50 mg + 300 mg + 300 mg | E4: TABLETA | F4: =IFERROR(VLOOKUP(A4,TblDisponibilidad[],23,FALSE),"No Manejado") -> No Manejado
A5: 17703 | B5: EFAVIRENZ | C5: 600 mg | E5: TABLETA | F5: =IFERROR(VLOOKUP(A5,TblDisponibilidad[],23,FALSE),"No Manejado") -> No Manejado
A6: 45074 | B6: EFAVIRENZ + LAMIVUDINA + TENOFOVIR | C6: 400 mg + 300 mg + 300 mg | E6: TABLETA | F6: =IFERROR(VLOOKUP(A6,TblDisponibilidad[],23,FALSE),"No Manejado") -> No Manejado
A7: 30437 | B7: EMTRICITABINA + TENOFOVIR | C7: 200 mg + 300 mg | D7: 20 mL | E7: TABLETA | F7: =IFERROR(VLOOKUP(A7,TblDisponibilidad[],23,FALSE),"No Manejado") -> No Manejado
A8: 03302 | B8: ETAMBUTOL CLORHIDRATO | C8: 400 mg | D8: 3 mL | E8: TABLETA | F8: =IFERROR(VLOOKUP(A8,TblDisponibilidad[],23,FALSE),"No Manejado") -> No Manejado
